ConnectionError
redis.exceptions.ConnectionError: Error 99 connecting to localhost:6379. Cannot assign requested address.

Traceback (most recent call last)
File "/home/runner/workspace/.pythonlibs/lib/python3.11/site-packages/redis/connection.py", line 357, in connect
sock = self.retry.call_with_retry(
       
File "/home/runner/workspace/.pythonlibs/lib/python3.11/site-packages/redis/retry.py", line 62, in call_with_retry
return do()
       ^^^^
File "/home/runner/workspace/.pythonlibs/lib/python3.11/site-packages/redis/connection.py", line 358, in <lambda>
lambda: self._connect(), lambda error: self.disconnect(error)
        ^^^^^^^^^^^^^^^
File "/home/runner/workspace/.pythonlibs/lib/python3.11/site-packages/redis/connection.py", line 730, in _connect
raise err
^^^^^^^^^
File "/home/runner/workspace/.pythonlibs/lib/python3.11/site-packages/redis/connection.py", line 718, in _connect
sock.connect(socket_address)
^^^^^^^^^^^^^^^^^^^^^^^^^^^^
During handling of the above exception, another exception occurred:
File "/home/runner/workspace/.pythonlibs/lib/python3.11/site-packages/flask/app.py", line 2213, in __call__
return self.wsgi_app(environ, start_response)
       ^^^^^^^^^^^^^^^^^^^^^^^^^^^^^^^^^^^^^^
File "/home/runner/workspace/.pythonlibs/lib/python3.11/site-packages/flask/app.py", line 2193, in wsgi_app
response = self.handle_exception(e)
           ^^^^^^^^^^^^^^^^^^^^^^^^
File "/home/runner/workspace/.pythonlibs/lib/python3.11/site-packages/flask/app.py", line 2190, in wsgi_app
response = self.full_dispatch_request()
           ^^^^^^^^^^^^^^^^^^^^^^^^^^^^
File "/home/runner/workspace/.pythonlibs/lib/python3.11/site-packages/flask/app.py", line 1486, in full_dispatch_request
rv = self.handle_user_exception(e)
     ^^^^^^^^^^^^^^^^^^^^^^^^^^^^^
File "/home/runner/workspace/.pythonlibs/lib/python3.11/site-packages/flask/app.py", line 1484, in full_dispatch_request
rv = self.dispatch_request()
     ^^^^^^^^^^^^^^^^^^^^^^^
File "/home/runner/workspace/.pythonlibs/lib/python3.11/site-packages/flask/app.py", line 1469, in dispatch_request
return self.ensure_sync(self.view_functions[rule.endpoint])(**view_args)
       ^^^^^^^^^^^^^^^^^^^^^^^^^^^^^^^^^^^^^^^^^^^^^^^^^^^^^^^^^^^^^^^^^
File "/home/runner/workspace/frontend/direct_app.py", line 137, in dashboard
metrics = get_sustainability_metrics()
          ^^^^^^^^^^^^^^^^^^^^^^^^^^^^
File "/home/runner/workspace/.pythonlibs/lib/python3.11/site-packages/flask_caching/__init__.py", line 861, in decorated_function
cache_key = decorated_function.make_cache_key(f, *args, **kwargs)
            ^^^^^^^^^^^^^^^^^^^^^^^^^^^^^^^^^^^^^^^^^^^^^^^^^^^^^
File "/home/runner/workspace/.pythonlibs/lib/python3.11/site-packages/flask_caching/__init__.py", line 618, in make_cache_key
fname, version_data = self._memoize_version(
                      
File "/home/runner/workspace/.pythonlibs/lib/python3.11/site-packages/flask_caching/__init__.py", line 568, in _memoize_version
version_data_list = list(self.cache.get_many(*fetch_keys))
                         ^^^^^^^^^^^^^^^^^^^^^^^^^^^^^^^^
File "/home/runner/workspace/.pythonlibs/lib/python3.11/site-packages/cachelib/redis.py", line 86, in get_many
return [self.serializer.loads(x) for x in self._read_client.mget(prefixed_keys)]
                                          ^^^^^^^^^^^^^^^^^^^^^^^^^^^^^^^^^^^^^
File "/home/runner/workspace/.pythonlibs/lib/python3.11/site-packages/redis/commands/core.py", line 2009, in mget
return self.execute_command("MGET", *args, **options)
       ^^^^^^^^^^^^^^^^^^^^^^^^^^^^^^^^^^^^^^^^^^^^^^
File "/home/runner/workspace/.pythonlibs/lib/python3.11/site-packages/redis/client.py", line 559, in execute_command
return self._execute_command(*args, **options)
       ^^^^^^^^^^^^^^^^^^^^^^^^^^^^^^^^^^^^^^^
File "/home/runner/workspace/.pythonlibs/lib/python3.11/site-packages/redis/client.py", line 565, in _execute_command
conn = self.connection or pool.get_connection(command_name, **options)
                          ^^^^^^^^^^^^^^^^^^^^^^^^^^^^^^^^^^^^^^^^^^^^
File "/home/runner/workspace/.pythonlibs/lib/python3.11/site-packages/redis/connection.py", line 1422, in get_connection
connection.connect()
^^^^^^^^^^^^^^^^^^^^
File "/home/runner/workspace/.pythonlibs/lib/python3.11/site-packages/redis/connection.py", line 363, in connect
raise ConnectionError(self._error_message(e))
^^^^^^^^^^^^^^^^^^^^^^^^^^^^^^^^^^^^^^^^^^^^^
redis.exceptions.ConnectionError: Error 99 connecting to localhost:6379. Cannot assign requested address.
The debugger caught an exception in your WSGI application. You can now look at the traceback which led to the error.
To switch between the interactive traceback and the plaintext one, you can click on the "Traceback" headline. From the text traceback you can also create a paste of it.

Brought to you by DON'T PANIC, your friendly Werkzeug powered traceback interpreter.